werkzeug.exceptions.NotFound: 404 Not Found: The requested URL was not found on the server. If you entered the URL manually please check your spelling and try again.

Traceback (most recent call last)
File "/home/hb/yookye_site/replit/TravelMosaic/python_server/.venv/lib/python3.11/site-packages/flask/app.py", line 917, in full_dispatch_request
rv = self.dispatch_request()
     ^^^^^^^^^^^^^^^^^^^^^^^
File "/home/hb/yookye_site/replit/TravelMosaic/python_server/.venv/lib/python3.11/site-packages/flask/app.py", line 902, in dispatch_request
return self.ensure_sync(self.view_functions[rule.endpoint])(**view_args)  # type: ignore[no-any-return]
       ^^^^^^^^^^^^^^^^^^^^^^^^^^^^^^^^^^^^^^^^^^^^^^^^^^^^^^^^^^^^^^^^^
File "/home/hb/yookye_site/replit/TravelMosaic/python_server/app.py", line 62, in serve
return app.send_static_file('index.html')
       ^^^^^^^^^^^^^^^^^^^^^^^^^^^^^^^^^^
File "/home/hb/yookye_site/replit/TravelMosaic/python_server/.venv/lib/python3.11/site-packages/flask/app.py", line 326, in send_static_file
return send_from_directory(
       
File "/home/hb/yookye_site/replit/TravelMosaic/python_server/.venv/lib/python3.11/site-packages/flask/helpers.py", line 565, in send_from_directory
return werkzeug.utils.send_from_directory(  # type: ignore[return-value]
       
File "/home/hb/yookye_site/replit/TravelMosaic/python_server/.venv/lib/python3.11/site-packages/werkzeug/utils.py", line 575, in send_from_directory
raise NotFound()
^^^^^^^^^^^^^^^^
During handling of the above exception, another exception occurred:
File "/home/hb/yookye_site/replit/TravelMosaic/python_server/.venv/lib/python3.11/site-packages/flask/app.py", line 1536, in __call__
return self.wsgi_app(environ, start_response)
       ^^^^^^^^^^^^^^^^^^^^^^^^^^^^^^^^^^^^^^
File "/home/hb/yookye_site/replit/TravelMosaic/python_server/.venv/lib/python3.11/site-packages/flask/app.py", line 1514, in wsgi_app
response = self.handle_exception(e)
           ^^^^^^^^^^^^^^^^^^^^^^^^
File "/home/hb/yookye_site/replit/TravelMosaic/python_server/.venv/lib/python3.11/site-packages/flask_cors/extension.py", line 176, in wrapped_function
return cors_after_request(app.make_response(f(*args, **kwargs)))
                                            ^^^^^^^^^^^^^^^^^^
File "/home/hb/yookye_site/replit/TravelMosaic/python_server/.venv/lib/python3.11/site-packages/flask/app.py", line 1511, in wsgi_app
response = self.full_dispatch_request()
           ^^^^^^^^^^^^^^^^^^^^^^^^^^^^
File "/home/hb/yookye_site/replit/TravelMosaic/python_server/.venv/lib/python3.11/site-packages/flask/app.py", line 919, in full_dispatch_request
rv = self.handle_user_exception(e)
     ^^^^^^^^^^^^^^^^^^^^^^^^^^^^^
File "/home/hb/yookye_site/replit/TravelMosaic/python_server/.venv/lib/python3.11/site-packages/flask_cors/extension.py", line 176, in wrapped_function
return cors_after_request(app.make_response(f(*args, **kwargs)))
                                            ^^^^^^^^^^^^^^^^^^
File "/home/hb/yookye_site/replit/TravelMosaic/python_server/.venv/lib/python3.11/site-packages/flask/app.py", line 802, in handle_user_exception
return self.handle_http_exception(e)
       ^^^^^^^^^^^^^^^^^^^^^^^^^^^^^
File "/home/hb/yookye_site/replit/TravelMosaic/python_server/.venv/lib/python3.11/site-packages/flask/app.py", line 777, in handle_http_exception
return self.ensure_sync(handler)(e)  # type: ignore[no-any-return]
       ^^^^^^^^^^^^^^^^^^^^^^^^^^^^
File "/home/hb/yookye_site/replit/TravelMosaic/python_server/app.py", line 69, in not_found
return app.send_static_file('index.html')
       ^^^^^^^^^^^^^^^^^^^^^^^^^^^^^^^^^^
File "/home/hb/yookye_site/replit/TravelMosaic/python_server/.venv/lib/python3.11/site-packages/flask/app.py", line 326, in send_static_file
return send_from_directory(
       
File "/home/hb/yookye_site/replit/TravelMosaic/python_server/.venv/lib/python3.11/site-packages/flask/helpers.py", line 565, in send_from_directory
return werkzeug.utils.send_from_directory(  # type: ignore[return-value]
       
File "/home/hb/yookye_site/replit/TravelMosaic/python_server/.venv/lib/python3.11/site-packages/werkzeug/utils.py", line 575, in send_from_directory
raise NotFound()
^^^^^^^^^^^^^^^^
werkzeug.exceptions.NotFound: 404 Not Found: The requested URL was not found on the server. If you entered the URL manually please check your spelling and try again.
The debugger caught an exception in your WSGI application. You can now look at the traceback which led to the error.
To switch between the interactive traceback and the plaintext one, you can click on the "Traceback" headline. From the text traceback you can also create a paste of it. For code execution mouse-over the frame you want to debug and click on the console icon on the right side.

You can execute arbitrary Python code in the stack frames and there are some extra helpers available for introspection:

dump() shows all variables in the frame
dump(obj) dumps all that's known about the object