INFO:werkzeug:127.0.0.1 - - [29/Apr/2025 17:30:15] "GET /api/user HTTP/1.1" 500 -
Traceback (most recent call last):
  File "/home/hb/yookye_site/replit/TravelMosaic/python_server/.venv/lib/python3.11/site-packages/flask/app.py", line 1536, in __call__
    return self.wsgi_app(environ, start_response)
           ^^^^^^^^^^^^^^^^^^^^^^^^^^^^^^^^^^^^^^
  File "/home/hb/yookye_site/replit/TravelMosaic/python_server/.venv/lib/python3.11/site-packages/flask/app.py", line 1514, in wsgi_app
    response = self.handle_exception(e)
               ^^^^^^^^^^^^^^^^^^^^^^^^
  File "/home/hb/yookye_site/replit/TravelMosaic/python_server/.venv/lib/python3.11/site-packages/flask_cors/extension.py", line 176, in wrapped_function
    return cors_after_request(app.make_response(f(*args, **kwargs)))
                                                ^^^^^^^^^^^^^^^^^^^^
  File "/home/hb/yookye_site/replit/TravelMosaic/python_server/.venv/lib/python3.11/site-packages/flask/app.py", line 1511, in wsgi_app
    response = self.full_dispatch_request()
               ^^^^^^^^^^^^^^^^^^^^^^^^^^^^
  File "/home/hb/yookye_site/replit/TravelMosaic/python_server/.venv/lib/python3.11/site-packages/flask/app.py", line 919, in full_dispatch_request
    rv = self.handle_user_exception(e)
         ^^^^^^^^^^^^^^^^^^^^^^^^^^^^^
  File "/home/hb/yookye_site/replit/TravelMosaic/python_server/.venv/lib/python3.11/site-packages/flask_cors/extension.py", line 176, in wrapped_function
    return cors_after_request(app.make_response(f(*args, **kwargs)))
                                                ^^^^^^^^^^^^^^^^^^^^
  File "/home/hb/yookye_site/replit/TravelMosaic/python_server/.venv/lib/python3.11/site-packages/flask/app.py", line 917, in full_dispatch_request
    rv = self.dispatch_request()
         ^^^^^^^^^^^^^^^^^^^^^^^
  File "/home/hb/yookye_site/replit/TravelMosaic/python_server/.venv/lib/python3.11/site-packages/flask/app.py", line 902, in dispatch_request
    return self.ensure_sync(self.view_functions[rule.endpoint])(**view_args)  # type: ignore[no-any-return]
           ^^^^^^^^^^^^^^^^^^^^^^^^^^^^^^^^^^^^^^^^^^^^^^^^^^^^^^^^^^^^^^^^^^^^^^^^^^^^^^^^^^^^^^^^^^^^^^^^
  File "/home/hb/.pyenv/versions/3.11.11/lib/python3.11/concurrent/futures/_base.py", line 449, in result
    return self.__get_result()
           ^^^^^^^^^^^^^^^^^^^
  File "/home/hb/.pyenv/versions/3.11.11/lib/python3.11/concurrent/futures/_base.py", line 401, in __get_result
    raise self._exception
  File "/home/hb/yookye_site/replit/TravelMosaic/python_server/api/auth.py", line 142, in get_current_user
    user = await user_repo.get_by_id(user_id)
           ^^^^^^^^^^^^^^^^^^^^^^^^^^^^^^^^^^
TypeError: object User can't be used in 'await' expression
